Workbook

Sheet 摘要
B2: 阿爾法九週年｜MOMO × CYBERBIZ 商品上架落差報告
B3: 對照《MOMO × CYBERBIZ 商品與銷售執行計畫》2026.09.14 正式執行版 V6 附錄1／附錄2（V6 附錄內容與 V2 完全一致），與 2026-09-14 實際爬取的平台上架資料
B5: MOMO | E5: CYBERBIZ
B6: 方案 SKU 數 | C6: =COUNTA('MOMO 對比'!$B$3:$B$40) | E6: 方案 SKU 數 | F6: =COUNTA('CYBERBIZ 對比'!$B$3:$B$38)
B7: 已上架且售價一致 | C7: =COUNTIF('MOMO 對比'!$G$3:$G$40,"已上架，售價一致") | E7: 已上架且售價一致 | F7: =COUNTIF('CYBERBIZ 對比'!$G$3:$G$38,"已上架，售價一致")
B8: 已上架但售價／規格不符 | C8: =COUNTIF('MOMO 對比'!$G$3:$G$40,"已上架，售價不符")+COUNTIF('MOMO 對比'!$G$3:$G$40,"已上架，規格待確認") | E8: 已上架但售價／規格不符 | F8: =COUNTIF('CYBERBIZ 對比'!$G$3:$G$38,"已上架，售價不符")+COUNTIF('CYBERBIZ 對比'!$G$3:$G$38,"已上架，規格待確認")
B9: 尚未上架 | C9: =COUNTIF('MOMO 對比'!$G$3:$G$40,"尚未上架") | E9: 尚未上架 | F9: =COUNTIF('CYBERBIZ 對比'!$G$3:$G$38,"尚未上架")
B10: 方案銷售預估 | C10: =SUM('MOMO 對比'!$F$3:$F$40) | E10: 方案銷售預估 | F10: =SUM('CYBERBIZ 對比'!$F$3:$F$38)
B11: 尚未上架商品之預估金額缺口 | C11: =SUMIF('MOMO 對比'!$G$3:$G$40,"尚未上架",'MOMO 對比'!$F$3:$F$40) | E11: 尚未上架商品之預估金額缺口 | F11: =SUMIF('CYBERBIZ 對比'!$G$3:$G$38,"尚未上架",'CYBERBIZ 對比'!$F$3:$F$38)
B13: 兩平台合計｜尚未上架商品之預估金額缺口 | F13: =C11+F11
B14: ＝方案總預估 1,885,879 元中，以今天（9/14）平台實際上架狀況推算，仍缺口未上架部分的比例
B16: 怎麼看這份報告
B17: 0. 方案已更新到 V6：V6 只改了直播段落結構（四層→七段）與 MOMO 滿額贈機制（加碼券→100元線上券），附錄1／附錄2／附錄5 的 SKU 清單、售價、計畫數量、總額逐字不變，本比對結果與 V2 版本相同，不需重跑。
B18: 1.「已上架，售價不符」：商品頁已存在，但目前售價與方案不同，需請 Cherrie／Shamus 團隊改價，不算「未上架」。
B19: 2.「已上架，規格待確認」：商品頁存在但無法從頁面資訊確認對應的入數／規格（例如滴雞精禮盒未標示容量），需人工開頁核對。
B20: 3.「尚未上架」：MOMO／CYBERBIZ 搜尋與 sitemap 都找不到對應商品頁，含全新品項（雙湯組合、VIP 禮品卡、五品牌周邊等）與既有商品的新規格（如茶油剝皮辣椒 3 入）。
B21: 4. MOMO 目前另有 10 個現售即享券不在附錄1的38項清單內（例如 $799抵$888 舊面額券），詳見「MOMO 現有未列項目」分頁，建議確認是否於 9/19 前下架以免與新券混淆。
B22: 5. 資料來源：MOMO 以關鍵字「雞湯大叔／賴山嶼／雞湯桑／麵屋一燈」搜尋頁 JSON-LD 直接讀取；CYBERBIZ 以 sitemap.xml 逐頁讀取，皆為 2026-09-14 即時抓取，非附錄提供資料，僅供上架落差比對，實際請以平台後台為準。
B24: 狀態圖例
B25: 已上架，售價一致
B26: 已上架，售價不符
B27: 已上架，規格待確認
B28: 尚未上架

Sheet MOMO 對比
A1: MOMO 對比｜依附錄，共 38 項，方案合計 1,518,922 元
A2: 分類 | B2: 商品名稱 | C2: 規格 | D2: 方案售價 | E2: 計畫數量 | F2: 銷售預估（元） | G2: 上架狀態 | H2: 目前售價 | I2: 目前商品位置 | J2: 備註
A3: VIP禮品卡 | B3: 999元VIP禮品卡 | C3: 實體卡，面額999元 | D3: 999 | E3: 200 | F3: =D3*E3 | G3: 尚未上架 | I3: —
A4: 飲品 | B4: 輕百香果氣泡烏龍 | C4: 6入 | D4: 415 | E4: 80 | F4: =D4*E4 | G4: 尚未上架 | I4: — | J4: momo 搜尋不到「輕百香果氣泡烏龍」任何商品頁
A5: 飲品 | B5: 輕百香果氣泡烏龍 | C5: 12入 | D5: 649 | E5: 40 | F5: =D5*E5 | G5: 尚未上架 | I5: —
A6: 飲品 | B6: 輕百香果氣泡烏龍 | C6: 24入 | D6: 1200 | E6: 20 | F6: =D6*E6 | G6: 尚未上架 | I6: —
A7: 飲品 | B7: 百香土鳳梨氣泡飲 | C7: 6入 | D7: 415 | E7: 40 | F7: =D7*E7 | G7: 尚未上架 | I7: — | J7: momo 搜尋不到「百香土鳳梨氣泡飲」任何商品頁
A8: 飲品 | B8: 百香土鳳梨氣泡飲 | C8: 12入 | D8: 649 | E8: 20 | F8: =D8*E8 | G8: 尚未上架 | I8: —
A9: 飲品 | B9: 百香土鳳梨氣泡飲 | C9: 24入 | D9: 1200 | E9: 8 | F9: =D9*E9 | G9: 尚未上架 | I9: —
A10: 醬料 | B10: 雞湯大叔×賴山嶼 青花椒辣椒醬240g | C10: 1入（僅MOMO） | D10: 330 | E10: 50 | F10: =D10*E10 | G10: 已上架，售價一致 | H10: 330 | I10: i_code 15250521
A11: 醬料 | B11: 雞湯大叔×賴山嶼 青花椒辣椒醬240g | C11: 2入（僅MOMO） | D11: 650 | E11: 80 | F11: =D11*E11 | G11: 已上架，售價一致 | H11: 650 | I11: i_code 15235085
A12: 醬料 | B12: 雞湯大叔×賴山嶼 青花椒辣椒醬240g | C12: 3入 | D12: 930 | E12: 160 | F12: =D12*E12 | G12: 已上架，售價一致 | H12: 930 | I12: i_code 15634154
A13: 醬料 | B13: 雞湯大叔×洄瀾醬人 茶油剝皮辣椒240g | C13: 1入（僅MOMO） | D13: 330 | E13: 20 | F13: =D13*E13 | G13: 已上架，售價不符 | H13: 280 | I13: i_code 15356778 | J13: 現售價比方案少 50 元
A14: 醬料 | B14: 雞湯大叔×洄瀾醬人 茶油剝皮辣椒240g | C14: 2入（僅MOMO） | D14: 650 | E14: 115 | F14: =D14*E14 | G14: 已上架，售價不符 | H14: 640 | I14: i_code 15642252 | J14: 現售價比方案少 10 元
A15: 醬料 | B15: 雞湯大叔×洄瀾醬人 茶油剝皮辣椒240g | C15: 3入 | D15: 930 | E15: 20 | F15: =D15*E15 | G15: 尚未上架 | I15: — | J15: momo 目前只有 1／2 入，無 3 入商品頁
A16: 雞精 | B16: 快樂雞滴雞精60ml | C16: 10包組 | D16: 790 | E16: 40 | F16: =D16*E16 | G16: 已上架，售價一致 | H16: 790 | I16: i_code 15414344
A17: 雞精 | B17: 快樂雞滴雞精禮盒 | C17: 6入（650元為推廣價） | D17: 650 | E17: 80 | F17: =D17*E17 | G17: 已上架，售價一致 | H17: 650 | I17: i_code 15127931
A18: 雞湯與禮盒 | B18: 蛤蜊雞湯460g | C18: 5包組 | D18: 849 | E18: 120 | F18: =D18*E18 | G18: 已上架，售價一致 | H18: 849 | I18: i_code 15491916
A19: 雞湯與禮盒 | B19: 黑松露牛肝菌雞湯禮盒 | C19: 1入（僅MOMO） | D19: 599 | E19: 20 | F19: =D19*E19 | G19: 已上架，售價一致 | H19: 599 | I19: i_code 15126499
A20: 雞湯與禮盒 | B20: 黑松露牛肝菌雞湯禮盒 | C20: 2入 | D20: 849 | E20: 40 | F20: =D20*E20 | G20: 已上架，售價一致 | H20: 849 | I20: i_code 15474320
A21: 雞湯與禮盒 | B21: 椒香成雙禮盒 | C21: 青花椒辣椒醬240g×1＋茶油剝皮辣椒240g×1 | D21: 799 | E21: 60 | F21: =D21*E21 | G21: 尚未上架 | I21: —
A22: 雞湯與禮盒 | B22: 泰鮮雙享組 | C22: 蛤蜊雞湯460g×3＋打拋貢丸×2 | D22: 888 | E22: 40 | F22: =D22*E22 | G22: 已上架，售價一致 | H22: 888 | I22: i_code 15633823
A23: 娘娘聯名 | B23: 娘娘聯名打拋貢丸（MOMO） | C23: 4包組 | D23: 799 | E23: 200 | F23: =D23*E23 | G23: 已上架，售價一致 | H23: 799 | I23: i_code 15540751 | J23: 商品頁名稱為「泰度打拋摃丸」
A24: 娘娘聯名 | B24: 娘娘聯名泰Chill打拋豬煎餃 | C24: 3包組 | D24: 649 | E24: 80 | F24: =D24*E24 | G24: 尚未上架 | I24: —
A25: 娘娘聯名 | B25: 娘娘聯名泰Chill打拋豬煎餃 | C25: 5包組 | D25: 845 | E25: 80 | F25: =D25*E25 | G25: 尚未上架 | I25: —
A26: 娘娘聯名 | B26: 娘娘駕到套組 | C26: 打拋豬煎餃×2＋打拋貢丸×2 | D26: 777 | E26: 40 | F26: =D26*E26 | G26: 尚未上架 | I26: —
A27: 新品雙湯組 | B27: 雙湯組合（MOMO） | C27: 御膳花膠×1＋北海道鮮貝×1＋青花椒辣椒醬×1 | D27: 666 | E27: 80 | F27: =D27*E27 | G27: 尚未上架 | I27: — | J27: 第三層重點零售商品，直播主打新品
A28: 新品雙湯組 | B28: 雙湯組合（MOMO） | C28: 御膳花膠×2＋北海道鮮貝×2＋青花椒辣椒醬×1 | D28: 999 | E28: 40 | F28: =D28*E28 | G28: 尚未上架 | I28: —
A29: 新品雙湯組 | B29: 雙湯組合（MOMO） | C29: 御膳花膠×3＋北海道鮮貝×3＋青花椒辣椒醬×1 | D29: 1299 | E29: 20 | F29: =D29*E29 | G29: 尚未上架 | I29: —
A30: Broth & Paws | B30: Broth & Paws 寵物餐包－蔬果燉雞 | C30: 10入 | D30: 888 | E30: 20 | F30: =D30*E30 | G30: 尚未上架 | I30: —
A31: Broth & Paws | B31: Broth & Paws 寵物餐包（MOMO） | C31: 20入 | D31: 1688 | E31: 8 | F31: =D31*E31 | G31: 尚未上架 | I31: —
A32: Broth & Paws | B32: Broth & Paws 肉泥條 | C32: 10入 | D32: 149 | E32: 40 | F32: =D32*E32 | G32: 尚未上架 | I32: —
A33: Broth & Paws | B33: Broth & Paws 肉泥條 | C33: 20入 | D33: 249 | E33: 20 | F33: =D33*E33 | G33: 尚未上架 | I33: —
A34: Broth & Paws | B34: 安心陪伴組（MOMO） | C34: 寵物餐包10入＋肉泥條10入 | D34: 999 | E34: 40 | F34: =D34*E34 | G34: 尚未上架 | I34: —
A35: 周邊商品 | B35: 雞湯大叔廚師娃娃 | C35: 單品 | D35: 199 | E35: 20 | F35: =D35*E35 | G35: 尚未上架 | I35: —
A36: 周邊商品 | B36: 雞湯桑娃娃 | C36: 單品 | D36: 199 | E36: 20 | F36: =D36*E36 | G36: 尚未上架 | I36: —
A37: 周邊商品 | B37: 麵屋一燈16週年小夜燈 | C37: 單品 | D37: 299 | E37: 20 | F37: =D37*E37 | G37: 尚未上架 | I37: —
A38: 周邊商品 | B38: 賴山嶼種子盲盒 | C38: 單品 | D38: 199 | E38: 20 | F38: =D38*E38 | G38: 尚未上架 | I38: —
A39: 周邊商品 | B39: 撈王九宮格老火鍋磁鐵 | C39: 單品 | D39: 149 | E39: 20 | F39: =D39*E39 | G39: 尚未上架 | I39: —
A40: 周邊商品 | B40: 五品牌九週年紀念組 | C40: 五品牌周邊各1件（共5件） | D40: 999 | E40: 32 | F40: =D40*E40 | G40: 尚未上架 | I40: —
...

Sheet CYBERBIZ 對比
A1: CYBERBIZ 對比｜依附錄，共 36 項，方案合計 366,957 元
A2: 分類 | B2: 商品名稱 | C2: 規格 | D2: 方案售價 | E2: 計畫數量 | F2: 銷售預估（元） | G2: 上架狀態 | H2: 目前售價 | I2: 目前商品位置 | J2: 備註
A3: VIP禮品卡 | B3: 999元VIP禮品卡 | C3: 實體卡，面額999元 | D3: 999 | E3: 50 | F3: =D3*E3 | G3: 尚未上架 | I3: —
A4: 飲品 | B4: 輕百香果氣泡烏龍 | C4: 6入 | D4: 415 | E4: 20 | F4: =D4*E4 | G4: 尚未上架 | I4: — | J4: CYBERBIZ 搜尋不到「輕百香果氣泡烏龍」任何商品頁
A5: 飲品 | B5: 輕百香果氣泡烏龍 | C5: 12入 | D5: 649 | E5: 10 | F5: =D5*E5 | G5: 尚未上架 | I5: —
A6: 飲品 | B6: 輕百香果氣泡烏龍 | C6: 24入 | D6: 1200 | E6: 5 | F6: =D6*E6 | G6: 尚未上架 | I6: —
A7: 飲品 | B7: 百香土鳳梨氣泡飲 | C7: 6入 | D7: 415 | E7: 10 | F7: =D7*E7 | G7: 已上架，售價一致 | H7: 415 | I7: /products/百香土鳳梨氣泡飲
A8: 飲品 | B8: 百香土鳳梨氣泡飲 | C8: 12入 | D8: 649 | E8: 5 | F8: =D8*E8 | G8: 尚未上架 | I8: — | J8: 只有 6 入與 24 入兩個商品頁，沒有 12 入
A9: 飲品 | B9: 百香土鳳梨氣泡飲 | C9: 24入 | D9: 1200 | E9: 2 | F9: =D9*E9 | G9: 已上架，售價不符 | H9: 1650 | I9: /products/百香土鳳梨氣泡飲-賴山嶼 | J9: 現售價比方案貴 450 元
A10: 飲品 | B10: 翡翠檸檬康普氣泡茶 | C10: 3入（僅CYBERBIZ） | D10: 269 | E10: 40 | F10: =D10*E10 | G10: 已上架，售價一致 | H10: 269 | I10: /products/雞湯大叔xkai_翡翠檸檬康普氣泡茶 | J10: 同一商品頁含 3／6／8 入三種容量選項
A11: 飲品 | B11: 翡翠檸檬康普氣泡茶 | C11: 6入（僅CYBERBIZ） | D11: 510 | E11: 30 | F11: =D11*E11 | G11: 已上架，售價一致 | H11: 510 | I11: /products/雞湯大叔xkai_翡翠檸檬康普氣泡茶
A12: 飲品 | B12: 翡翠檸檬康普氣泡茶 | C12: 8入（僅CYBERBIZ） | D12: 640 | E12: 20 | F12: =D12*E12 | G12: 已上架，售價一致 | H12: 640 | I12: /products/雞湯大叔xkai_翡翠檸檬康普氣泡茶
A13: 醬料 | B13: 雞湯大叔×賴山嶼 青花椒辣椒醬240g | C13: 3入 | D13: 930 | E13: 40 | F13: =D13*E13 | G13: 已上架，售價不符 | H13: 899 | I13: /products/青花椒辣醬3入 | J13: 現售價比方案少 31 元
A14: 醬料 | B14: 雞湯大叔×洄瀾醬人 茶油剝皮辣椒240g | C14: 3入 | D14: 930 | E14: 5 | F14: =D14*E14 | G14: 已上架，售價不符 | H14: 960 | I14: /products/茶油剝皮辣椒 | J14: 現售價比方案貴 30 元；同頁另賣 1入$390、2入$699，這兩規格依方案應為「僅MOMO」專屬，需確認是否要下架
A15: 雞精 | B15: 快樂雞滴雞精60ml | C15: 10包組 | D15: 790 | E15: 10 | F15: =D15*E15 | G15: 已上架，規格待確認 | H15: 990 | I15: /products/滴雞精禮盒 | J15: CYBERBIZ 只有「雞湯大叔快樂雞滴雞精」一個商品頁、現價 990 元，未標示是 60ml 或禮盒規格，與方案兩個品項的售價都對不上，需人工核對規格
A16: 雞精 | B16: 快樂雞滴雞精禮盒 | C16: 6入（650元為推廣價） | D16: 650 | E16: 20 | F16: =D16*E16 | G16: 已上架，規格待確認 | H16: 990 | I16: /products/滴雞精禮盒 | J16: 同上，可能與上一列是同一商品頁
A17: 雞湯與禮盒 | B17: 蛤蜊雞湯460g | C17: 5包組 | D17: 849 | E17: 30 | F17: =D17*E17 | G17: 已上架，售價不符 | H17: 999 | I17: /products/蛤蜊雞湯 | J17: 現售價比方案貴 150 元
A18: 雞湯與禮盒 | B18: 黑松露牛肝菌雞湯禮盒 | C18: 2入 | D18: 849 | E18: 10 | F18: =D18*E18 | G18: 已上架，售價不符 | H18: 999 | I18: /products/松露雞湯禮盒 | J18: 現售價比方案貴 150 元
A19: 雞湯與禮盒 | B19: 椒香成雙禮盒 | C19: 青花椒辣椒醬240g×1＋茶油剝皮辣椒240g×1 | D19: 799 | E19: 15 | F19: =D19*E19 | G19: 已上架，售價不符 | H19: 1099 | I19: /products/經典限定椒香成雙禮盒-內含青花椒辣醬茶油剝皮辣椒各1瓶 | J19: 現售價比方案貴 300 元
A20: 雞湯與禮盒 | B20: 泰鮮雙享組 | C20: 蛤蜊雞湯460g×3＋打拋貢丸×2 | D20: 888 | E20: 10 | F20: =D20*E20 | G20: 尚未上架 | I20: —
A21: 娘娘聯名 | B21: 娘娘聯名打拋貢丸（CYBERBIZ） | C21: 3包組 | D21: 630 | E21: 50 | F21: =D21*E21 | G21: 已上架，售價一致 | H21: 630 | I21: /products/泰度打拋摃丸
A22: 娘娘聯名 | B22: 娘娘聯名泰Chill打拋豬煎餃 | C22: 3包組 | D22: 649 | E22: 20 | F22: =D22*E22 | G22: 尚未上架 | I22: —
A23: 娘娘聯名 | B23: 娘娘聯名泰Chill打拋豬煎餃 | C23: 5包組 | D23: 845 | E23: 20 | F23: =D23*E23 | G23: 尚未上架 | I23: —
A24: 娘娘聯名 | B24: 娘娘駕到套組 | C24: 打拋豬煎餃×2＋打拋貢丸×2 | D24: 777 | E24: 10 | F24: =D24*E24 | G24: 尚未上架 | I24: —
A25: 新品雙湯組 | B25: 雙湯組合（CYBERBIZ） | C25: 御膳花膠×1＋北海道鮮貝×1＋輕百香果氣泡烏龍×2 | D25: 499 | E25: 20 | F25: =D25*E25 | G25: 尚未上架 | I25: — | J25: 第三層重點零售商品，直播主打新品
A26: 新品雙湯組 | B26: 雙湯組合（CYBERBIZ） | C26: 御膳花膠×2＋北海道鮮貝×2＋輕百香果氣泡烏龍×4 | D26: 950 | E26: 10 | F26: =D26*E26 | G26: 尚未上架 | I26: —
A27: 新品雙湯組 | B27: 雙湯組合（CYBERBIZ） | C27: 御膳花膠×3＋北海道鮮貝×3＋輕百香果氣泡烏龍×6 | D27: 1399 | E27: 5 | F27: =D27*E27 | G27: 尚未上架 | I27: —
A28: Broth & Paws | B28: Broth & Paws 寵物餐包－蔬果燉雞 | C28: 10入 | D28: 888 | E28: 5 | F28: =D28*E28 | G28: 已上架，售價不符 | H28: 750 | I28: /products/爪爪兄弟餐包-蔬果燉雞-狗狗主食餐包 | J28: 現售價比方案少 138 元；sitemap.xml 網址已失效，正確網址多了「-狗狗主食餐包」
A29: Broth & Paws | B29: Broth & Paws 寵物餐包（CYBERBIZ） | C29: 20入 | D29: 1490 | E29: 2 | F29: =D29*E29 | G29: 已上架，售價不符 | H29: 1450 | I29: /products/爪爪兄弟餐包-蔬果燉雞-狗狗主食餐包 | J29: 現售價比方案少 40 元；與上一列同一商品頁的另一規格
A30: Broth & Paws | B30: Broth & Paws 肉泥條 | C30: 10入 | D30: 149 | E30: 10 | F30: =D30*E30 | G30: 尚未上架 | I30: —
A31: Broth & Paws | B31: Broth & Paws 肉泥條 | C31: 20入 | D31: 249 | E31: 5 | F31: =D31*E31 | G31: 尚未上架 | I31: —
A32: Broth & Paws | B32: 安心陪伴組（CYBERBIZ） | C32: 寵物餐包10入＋肉泥條20入 | D32: 1099 | E32: 10 | F32: =D32*E32 | G32: 尚未上架 | I32: —
A33: 周邊商品 | B33: 雞湯大叔廚師娃娃 | C33: 單品 | D33: 199 | E33: 5 | F33: =D33*E33 | G33: 尚未上架 | I33: —
A34: 周邊商品 | B34: 雞湯桑娃娃 | C34: 單品 | D34: 199 | E34: 5 | F34: =D34*E34 | G34: 尚未上架 | I34: —
A35: 周邊商品 | B35: 麵屋一燈16週年小夜燈 | C35: 單品 | D35: 299 | E35: 5 | F35: =D35*E35 | G35: 尚未上架 | I35: —
A36: 周邊商品 | B36: 賴山嶼種子盲盒 | C36: 單品 | D36: 199 | E36: 5 | F36: =D36*E36 | G36: 尚未上架 | I36: —
A37: 周邊商品 | B37: 撈王九宮格老火鍋磁鐵 | C37: 單品 | D37: 149 | E37: 5 | F37: =D37*E37 | G37: 尚未上架 | I37: —
A38: 周邊商品 | B38: 五品牌九週年紀念組 | C38: 五品牌周邊各1件（共5件） | D38: 999 | E38: 8 | F38: =D38*E38 | G38: 尚未上架 | I38: —
E39: 合計 | F39: =SUM(F3:F38)

Sheet MOMO 現有未列項目
A1: MOMO 現有上架、但不在附錄1的38項清單內的商品（共 10 項）
A2: 商品編號 | B2: 商品名稱 | C2: 目前售價 | D2: 備註／建議
A3: i_code 15394742 | B3: 【BROTH MASTER 雞湯大叔】$482雞湯火鍋套餐(雪花牛或梅花豬擇一)好禮即享券 | C3: $438 | D3: 看似店內套餐即享券，與附錄5五品牌套餐券不同名稱，需確認是否為舊版本
A4: i_code 15467510 | B4: 【阿爾法餐飲集團】雞湯大叔/雞湯桑/麵屋一燈/賴山嶼通用 $799抵$888好禮即享券(一次抵用型) | C4: $799 | D4: 面額 799 抵 888，與方案新券「799 抵 999」(15689826) 機制相同但面額不同，恐與新券混淆，建議下架或說明
A5: i_code 15467509 | B5: 【BROTH MASTER 雞湯大叔】$1494泰國季限定-泰chill雙人套餐好禮即享券 | C5: $1299 | D5: 不在附錄1／附錄5清單內
A6: i_code 15394739 | B6: 【BROTH MASTER 雞湯大叔】$646雞湯火鍋套餐(海鮮拼盤)好禮即享券 | C6: $587 | D6: 不在附錄1／附錄5清單內
A7: i_code 15394740 | B7: 【BROTH MASTER 雞湯大叔】$613松露野菇雞湯火鍋套餐(板腱牛)好禮即享券 | C7: $557 | D7: 不在附錄1／附錄5清單內
A8: i_code 14614419 | B8: 【雞湯桑】$298松露旨味雞白湯拉麵 好禮即享券 | C8: $298 | D8: 單品券，與附錄5「雞湯桑店內單人298/雙人608」套餐券名稱不同，需確認對應關係
A9: i_code 14614418 | B9: 【雞湯桑】$248東京雞白湯拉麵 好禮即享券 | C9: $248 | D9: 同上
A10: i_code 14614420 | B10: 【雞湯桑】$298海膽魚子雞白湯拉麵 好禮即享券 | C10: $298 | D10: 同上
A11: i_code 14614416 | B11: 【雞湯桑】$248櫻花柚子拉麵 好禮即享券 | C11: $248 | D11: 同上
A12: i_code 14614417 | B12: 【雞湯桑】$248松露牛肝菌拉麵 好禮即享券 | C12: $248 | D12: 同上
